<?xml version="1.0"?>
<robot name="my_mobile_robot">
  <link name="world"/>

  <link name="base_link">
    <inertial>
      <mass value="1.0"/>
      <origin xyz="0 0 0"/>
      <inertia ixx="1.0" ixy="0.0" ixz="0.0" iyy="1.0" iyz="0.0" izz="1.0"/>
    </inertial>
  </link>

  <link name="wheel_left">
    <inertial>
      <mass value="0.5"/>
      <origin xyz="0 0 0"/>
      <inertia ixx="0.01" ixy="0.0" ixz="0.0" iyy="0.01" iyz="0.0" izz="0.01"/>
    </inertial>
  </link>

  <link name="wheel_right">
    <inertial>
      <mass value="0.5"/>
      <origin xyz="0 0 0"/>
      <inertia ixx="0.01" ixy="0.0" ixz="0.0" iyy="0.01" iyz="0.0" izz="0.01"/>
    </inertial>
  </link>

  <joint name="fixed_joint" type="fixed">
    <parent link="world"/>
    <child link="base_link"/>
    <origin xyz="0 0 0"/>
  </joint>

  <joint name="left_wheel_joint" type="revolute">
    <parent link="base_link"/>
    <child link="wheel_left"/>
    <origin xyz="-0.3 0.2 0"/>
    <axis xyz="0 0 1"/>
    <limit effort="10.0" velocity="10.0"/>
  </joint>

  <joint name="right_wheel_joint" type="revolute">
    <parent link="base_link"/>
    <child link="wheel_right"/>
    <origin xyz="-0.3 -0.2 0"/>
    <axis xyz="0 0 1"/>
    <limit effort="10.0" velocity="10.0"/>
  </joint>
</robot>
